Exception on /api/get_leaderboard [POST]
Traceback (most recent call last):
  File "/home/acm/Documents/code/byte_le_royale_2021/server/Server.py", line 131, in get_leaderboard
    abort(500, description="No data to return for leaderboard yet")
  File "/home/acm/.local/lib/python3.8/site-packages/werkzeug/exceptions.py", line 940, in abort
    _aborter(status, *args, **kwargs)
  File "/home/acm/.local/lib/python3.8/site-packages/werkzeug/exceptions.py", line 923, in __call__
    raise self.mapping[code](*args, **kwargs)
werkzeug.exceptions.InternalServerError: 500 Internal Server Error: No data to return for leaderboard yet

During handling of the above exception, another exception occurred:

Traceback (most recent call last):
  File "/home/acm/.local/lib/python3.8/site-packages/flask/app.py", line 1516, in full_dispatch_request
    rv = self.dispatch_request()
  File "/home/acm/.local/lib/python3.8/site-packages/flask/app.py", line 1502, in dispatch_request
    return self.ensure_sync(self.view_functions[rule.endpoint])(**req.view_args)
  File "/home/acm/Documents/code/byte_le_royale_2021/server/Server.py", line 131, in get_leaderboard
    abort(500, description="No data to return for leaderboard yet")
  File "/home/acm/.local/lib/python3.8/site-packages/werkzeug/exceptions.py", line 940, in abort
    _aborter(status, *args, **kwargs)
  File "/home/acm/.local/lib/python3.8/site-packages/werkzeug/exceptions.py", line 923, in __call__
    raise self.mapping[code](*args, **kwargs)
werkzeug.exceptions.InternalServerError: 500 Internal Server Error: 500 Internal Server Error: No data to return for leaderboard yet

During handling of the above exception, another exception occurred:

Traceback (most recent call last):
  File "/home/acm/.local/lib/python3.8/site-packages/flask/app.py", line 2073, in wsgi_app
    response = self.full_dispatch_request()
  File "/home/acm/.local/lib/python3.8/site-packages/flask/app.py", line 1518, in full_dispatch_request
    rv = self.handle_user_exception(e)
  File "/home/acm/.local/lib/python3.8/site-packages/flask/app.py", line 1386, in handle_user_exception
    return self.handle_http_exception(e)
  File "/home/acm/.local/lib/python3.8/site-packages/flask/app.py", line 1326, in handle_http_exception
    return self.ensure_sync(handler)(e)
  File "/home/acm/Documents/code/byte_le_royale_2021/server/Server.py", line 72, in handle_exception
    response.data = json.dumps({
  File "/usr/lib/python3.8/json/__init__.py", line 231, in dumps
    return _default_encoder.encode(obj)
  File "/usr/lib/python3.8/json/encoder.py", line 199, in encode
    chunks = self.iterencode(o, _one_shot=True)
  File "/usr/lib/python3.8/json/encoder.py", line 257, in iterencode
    return _iterencode(o, 0)
  File "/usr/lib/python3.8/json/encoder.py", line 179, in default
    raise TypeError(f'Object of type {o.__class__.__name__} '
TypeError: Object of type InternalServerError is not JSON serializable
Error: No data to return for leaderboard
Exception in get_leaderboard: 500 Internal Server Error: No data to return for leaderboard yet
Error: No data to return for leaderboard
Exception in get_leaderboard: 500 Internal Server Error: No data to return for leaderboard yet
Error: No data to return for leaderboard
Exception in get_leaderboard: 500 Internal Server Error: No data to return for leaderboard yet
Error: No data to return for leaderboard
Error: No data to return for leaderboard
Error: No data to return submissions_stats for d1965e2c-8614-4019-a37e-b190b03abf6c
Error: No data to return submissions_stats for d1965e2c-8614-4019-a37e-b190b03abf6c
Returning get_team_score_over_time for d1965e2c-8614-4019-a37e-b190b03abf6c at IP 134.129.91.223
Error: No data to return team_score_over_time for d1965e2c-8614-4019-a37e-b190b03abf6c
Returning get_team_score_over_time for d1965e2c-8614-4019-a37e-b190b03abf6c at IP 134.129.91.223
Error: No data to return team_score_over_time for d1965e2c-8614-4019-a37e-b190b03abf6c
Returning get_team_score_over_time for d1965e2c-8614-4019-a37e-b190b03abf6c at IP 134.129.91.223
Error: No data to return team_score_over_time for d1965e2c-8614-4019-a37e-b190b03abf6c
Returning get_team_score_over_time for d1965e2c-8614-4019-a37e-b190b03abf6c at IP 134.129.91.223
Error: No data to return team_score_over_time for d1965e2c-8614-4019-a37e-b190b03abf6c
Returning get_team_score_over_time for d1965e2c-8614-4019-a37e-b190b03abf6c at IP 134.129.91.223
Error: No data to return team_score_over_time for d1965e2c-8614-4019-a37e-b190b03abf6c
ratelimit 5 per 1 minute (134.129.91.223) exceeded at endpoint: get_team_score_over_time
Exception in get_seed_from_run: invalid input syntax for type uuid: "gs"
LINE 1: SELECT get_seed_for_run('gs', 42)
                                ^

Exception in get_seed_from_run: 'get_seed_from_run'
Returning seed for runid 42 for team d1965e2c-8614-4019-a37e-b190b03abf6c at IP 134.129.91.223
Exception in get_seed_from_run: 'get_seed_from_run'
Returning seed for runid 42 for team d1965e2c-8614-4019-a37e-b190b03abf6c at IP 134.129.91.223
Exception in get_seed_from_run: 'get_seed_from_run'
Exception on /api/get_seed_from_run [POST]
Traceback (most recent call last):
  File "/home/acm/Documents/code/byte_le_royale_2021/server/Server.py", line 246, in get_seed_from_run
    else:
KeyError: 'get_seed_from_run'

During handling of the above exception, another exception occurred:

Traceback (most recent call last):
  File "/home/acm/.local/lib/python3.8/site-packages/flask/app.py", line 2073, in wsgi_app
    response = self.full_dispatch_request()
  File "/home/acm/.local/lib/python3.8/site-packages/flask/app.py", line 1516, in full_dispatch_request
    rv = self.dispatch_request()
  File "/home/acm/.local/lib/python3.8/site-packages/flask/app.py", line 1516, in full_dispatch_request
    rv = self.dispatch_request()
  File "/home/acm/.local/lib/python3.8/site-packages/flask/app.py", line 1502, in dispatch_request
    return self.ensure_sync(self.view_functions[rule.endpoint])(**req.view_args)
  File "/home/acm/.local/lib/python3.8/site-packages/flask_limiter/extension.py", line 732, in __inner
    return current_app.ensure_sync(obj)(*a, **k)
  File "/home/acm/Documents/code/byte_le_royale_2021/server/Server.py", line 252, in get_seed_from_run
    app.logger.error("Exception in get_seed_from_run: %s", str(e))
  File "/home/acm/Documents/code/byte_le_royale_2021/server/Server.py", line 252, in get_seed_from_run
    app.logger.error("Exception in get_seed_from_run: %s", str(e))
  File "/usr/lib/python3.8/bdb.py", line 88, in trace_dispatch
    return self.dispatch_line(frame)
  File "/usr/lib/python3.8/bdb.py", line 113, in dispatch_line
    if self.quitting: raise BdbQuit
bdb.BdbQuit
Returning seed for runid 42 for team d1965e2c-8614-4019-a37e-b190b03abf6c at IP 134.129.91.223
Returning seed for runid 42 for team d1965e2c-8614-4019-a37e-b190b03abf6c at IP 134.129.91.223
Exception on /api/get_seed_from_run [POST]
Traceback (most recent call last):
  File "/home/acm/.local/lib/python3.8/site-packages/flask/app.py", line 2073, in wsgi_app
    response = self.full_dispatch_request()
  File "/home/acm/.local/lib/python3.8/site-packages/flask/app.py", line 1519, in full_dispatch_request
    return self.finalize_request(rv)
  File "/home/acm/.local/lib/python3.8/site-packages/flask/app.py", line 1538, in finalize_request
    response = self.make_response(rv)
  File "/home/acm/.local/lib/python3.8/site-packages/flask/app.py", line 1701, in make_response
    raise TypeError(
TypeError: The view function for 'get_seed_from_run' did not return a valid response. The function either returned None or ended without a return statement.
Returning seed for runid 42 for team d1965e2c-8614-4019-a37e-b190b03abf6c at IP 134.129.91.223
Returning seed for runid 42 for team d1965e2c-8614-4019-a37e-b190b03abf6c at IP 134.129.91.223
Returning seed for runid 42 for team d1965e2c-8614-4019-a37e-b190b03abf6c at IP 134.129.91.223
Returning seed for runid 42 for team d1965e2c-8614-4019-a37e-b190b03abf6c at IP 134.129.91.223
Returning seed for runid 42 for team d1965e2c-8614-4019-a37e-b190b03abf6c at IP 134.129.91.223
Returning seed for runid 42 for team d1965e2c-8614-4019-a37e-b190b03abf6c at IP 134.129.91.223
Returning seed for runid 42 for team d1965e2c-8614-4019-a37e-b190b03abf6c at IP 134.129.91.223
Returning seed for runid 5 for team d1965e2c-8614-4019-a37e-b190b03abf6c at IP 134.129.91.223
Returning seed for runid 5 for team d1965e2c-8614-4019-a37e-b190b03abf6c at IP 134.129.91.223
Returning seed for runid 2 for team d1965e2c-8614-4019-a37e-b190b03abf6c at IP 134.129.91.223
Returning seed for runid 2 for team d1965e2c-8614-4019-a37e-b190b03abf6c at IP 134.129.91.223
Returning seed for runid 2 for team d1965e2c-8614-4019-a37e-b190b03abf6c at IP 134.129.91.223
Returning seed for runid 2 for team d1965e2c-8614-4019-a37e-b190b03abf6c at IP 134.129.91.223
Returning seed for runid 2 for team d1965e2c-8614-4019-a37e-b190b03abf6c at IP 134.129.91.223
